<?xml version="1.0" encoding="utf-8"?>
<!-- =================================================================================== -->
<!-- |    This document was autogenerated by xacro from mav_with_vi_sensor_robot_arm.gazebo | -->
<!-- |    EDITING THIS FILE BY HAND IS NOT RECOMMENDED                                 | -->
<!-- =================================================================================== -->
<!--
  Copyright 2015 Fadri Furrer, ASL, ETH Zurich, Switzerland
  Copyright 2015 Michael Burri, ASL, ETH Zurich, Switzerland
  Copyright 2015 Mina Kamel, ASL, ETH Zurich, Switzerland
  Copyright 2015 Janosch Nikolic, ASL, ETH Zurich, Switzerland
  Copyright 2015 Markus Achtelik, ASL, ETH Zurich, Switzerland

  Licensed under the Apache License, Version 2.0 (the "License");
  you may not use this file except in compliance with the License.
  You may obtain a copy of the License at

  http://www.apache.org/licenses/LICENSE-2.0

  Unless required by applicable law or agreed to in writing, software
  distributed under the License is distributed on an "AS IS" BASIS,
  WITHOUT WARRANTIES OR CONDITIONS OF ANY KIND, either express or implied.
  See the License for the specific language governing permissions and
  limitations under the License.
-->
<robot xmlns:xacro="http://www.ros.org/wiki/xacro" name="firefly">
  <xacro:macro name="firefly">
    <gazebo>
      <plugin name="gazebo_ros_control" filename="libgazebo_ros_control.so">
        <robotSimType>gazebo_ros_control/DefaultRobotHWSim</robotSimType>
        <legacyModeNS>true</legacyModeNS>
      </plugin>
    </gazebo>    
    
    <!--///////////////////////////////////////////////////////////////////////////////////////////////////////////////////////////////// -->
    <!-- =============================================================== -->
    <!-- ==================== ROS INTERFACE MACRO ====================== -->
    <!-- =============================================================== -->
    <link name="firefly/base_link"/>

    <!-- making the base joint for the manipulator  -->
    <joint name="virtual_joint" type="fixed">
      <parent link="firefly/base_link"/>
      <child link="firefly/wx250s/base_link"/>
    </joint>
    
    <!-- making the base link for the manipulator, lower deck  -->
    <link name="firefly/wx250s/base_link">
      <visual>
        <origin rpy="3.14159265359 0 -1.5707963268" xyz="0.1 0.0 0.02"/>
        <geometry>
          <mesh filename="package://rotors_description/meshes/wx250s/WXSA-250-M-1-Base.stl" scale="0.001 0.001 0.001"/>
        </geometry>
      </visual>
      <collision>
        <origin rpy="3.14159265359 0 -1.5707963268" xyz="0.1 0.0 0.02"/>
        <geometry>
          <mesh filename="package://rotors_description/meshes/wx250s/WXSA-250-M-1-Base.stl" scale="0.001 0.001 0.001"/>
        </geometry>
      </collision>
      <inertial>
        <origin rpy="3.14159265359 0 -1.5707963268" xyz="0.0 0.0 0.0"/>
        <mass value="0.001"/>
        <inertia ixx="0.0021150000" ixy="-0.0000163500" ixz="0.0000006998" iyy="0.0006921000" iyz="0.0000464200" izz="0.0025240000"/>
      </inertial>
    </link>
    <!-- making the waist joint -->
    <joint name="wx250s_waist" type="revolute">
      <axis xyz="0 0 1"/>
      <limit effort="100" lower="-3.14159265359" upper="3.14159265359" velocity="3.14159265359"/>
      <origin rpy="3.14159265359 0 -1.5707963268" xyz="0.1 0.0 0.0916"/>
      <parent link="firefly/wx250s/base_link"/>
      <child link="firefly/wx250s/shoulder_link"/>
    </joint>
    <!-- making the waist servo -->
    <transmission name="wx250s_trans_waist">
      <type>transmission_interface/SimpleTransmission</type>
      <joint name="wx250s_waist">
        <!-- <hardwareInterface>hardware_interface/EffortJointInterface</hardwareInterface> -->
        <hardwareInterface>hardware_interface/PositionJointInterface</hardwareInterface>
      </joint>
      <actuator name="wx250s_waist_motor">
        <mechanicalReduction>1</mechanicalReduction>
      </actuator>
    </transmission>
    <!-- making the shoulder link -->
    <link name="firefly/wx250s/shoulder_link">
      <visual>
        <origin rpy="0.0 0.0 0.0" xyz="0 0 0.137"/>
        <geometry>
          <mesh filename="package://rotors_description/meshes/wx250s/WXSA-250-M-2-Shoulder.stl" scale="0.001 0.001 0.001"/>
        </geometry>
      </visual>
      <collision>
        <origin rpy="0.0 0.0 0.0" xyz="0 0 0.137"/>
        <geometry>
          <mesh filename="package://rotors_description/meshes/wx250s/WXSA-250-M-2-Shoulder.stl" scale="0.001 0.001 0.001"/>
        </geometry>
      </collision>
      <inertial>
        <origin rpy="0.0 0.0 0.0" xyz="0 0 0.0"/>
        <mass value="0.001"/>
        <inertia ixx="0.0003790000" ixy="0.0000000022" ixz="-0.0000003561" iyy="0.0005557000" iyz="0.0000012245" izz="0.0005889000"/>
      </inertial>
    </link>
    <!-- making the shoulder joint -->
    <joint name="wx250s_shoulder" type="revolute">
      <axis xyz="1 0 0"/>
      <limit effort="100" lower="-1.88495559215" upper="1.98967534727" velocity="3.14159265359"/>
      <origin rpy="0 0 0" xyz="0 0 0.165"/>
      <parent link="firefly/wx250s/shoulder_link"/>
      <child link="firefly/wx250s/upper_arm_link"/>
    </joint>
    <!-- making the shoulder servo -->
    <transmission name="wx250s_trans_shoulder">
      <type>transmission_interface/SimpleTransmission</type>
      <joint name="wx250s_shoulder">
        <!-- <hardwareInterface>hardware_interface/EffortJointInterface</hardwareInterface> -->
        <hardwareInterface>hardware_interface/PositionJointInterface</hardwareInterface>
      </joint>
      <actuator name="wx250s_shoulder_motor">
        <mechanicalReduction>1</mechanicalReduction>
      </actuator>
    </transmission>
    <!-- making the upper arm link, between the shoulder and the elbow -->
    <link name="firefly/wx250s/upper_arm_link">
      <visual>
        <origin rpy="0.0 0.0 0.0" xyz="0.0 0.0 0.0"/>
        <geometry>
          <mesh filename="package://rotors_description/meshes//wx250s/WXSA-250-M-3-UA.stl" scale="0.001 0.001 0.001"/>
        </geometry>
      </visual>
      <collision>
        <origin rpy="0.0 0.0 0.0" xyz="0.0 0.0 0.0"/>
        <geometry>
          <mesh filename="package://rotors_description/meshes//wx250s/WXSA-250-M-3-UA.stl" scale="0.001 0.001 0.001"/>
        </geometry>
      </collision>
      <inertial>
        <origin rpy="0.0 0.0 0.0" xyz="0.0 0.0 0.0"/>
        <mass value="0.001"/>
        <inertia ixx="0.0034630000" ixy="-0.0000000001" ixz="-0.0000000002" iyy="0.0035870000" iyz="0.0004272000" izz="0.0004566000"/>
      </inertial>
    </link>
    <!-- making the elbow joint, between the shoulder and the elbow -->
    <joint name="wx250s_elbow" type="revolute">
      <axis xyz="0 0 1"/>
      <limit effort="100" lower="-1.60570291183" upper="2.14675497995" velocity="3.14159265359"/>
      <origin rpy="0 1.5707963268 0" xyz="0.0 -0.05 0.25"/>
      <parent link="firefly/wx250s/upper_arm_link"/>
      <child link="firefly/wx250s/upper_forearm_link"/>
    </joint>
    <!-- making the elbow servo, between the shoulder and the elbow -->
    <transmission name="wx250s_trans_elbow">
      <type>transmission_interface/SimpleTransmission</type>
      <joint name="wx250s_elbow">
        <!-- <hardwareInterface>hardware_interface/EffortJointInterface</hardwareInterface> -->
        <hardwareInterface>hardware_interface/PositionJointInterface</hardwareInterface>
      </joint>
      <actuator name="wx250s_elbow_motor">
        <mechanicalReduction>1</mechanicalReduction>
      </actuator>
    </transmission>
    <!-- making the upper forearm link, for the rotation of the elbow -->
    <link name="firefly/wx250s/upper_forearm_link">
      <visual>
        <origin rpy="1.5707963268 3.14159265359 1.5707963268" xyz="0.0 0.0 0.0"/>
        <geometry>
          <mesh filename="package://rotors_description/meshes/wx250s/WXSA-250-M-4-UF.stl" scale="0.001 0.001 0.001"/>
        </geometry>
      </visual>
      <collision>
        <origin rpy="1.5707963268 3.14159265359 1.5707963268" xyz="0.0 0.0 0.0"/>
        <geometry>
          <mesh filename="package://rotors_description/meshes/wx250s/WXSA-250-M-4-UF.stl" scale="0.001 0.001 0.001"/>
        </geometry>
      </collision>
      <inertial>
        <origin rpy="0.0 0.0 0.0" xyz="0.0 0.0 0.0"/>
        <mass value="0.001"/>
        <inertia ixx="0.0000397100" ixy="0.0000023528" ixz="0" iyy="0.0008878000" iyz="0" izz="0.0008880000"/>
      </inertial>
    </link>
    <!-- making the forearm roll joint, for the rotation of the elbow -->
    <joint name="wx250s_forearm_roll" type="revolute">
      <axis xyz="0 -1 0"/>
      <limit effort="100" lower="-3.14159265359" upper="3.14159265359" velocity="3.14159265359"/>
      <origin rpy="0 0 0" xyz="0.0 -0.175 0.0"/>
      <parent link="firefly/wx250s/upper_forearm_link"/>
      <child link="firefly/wx250s/lower_forearm_link"/>
    </joint>
    <!-- making the forearm roll servo, for the rotation of the elbow -->
    <transmission name="wx250s_trans_forearm_roll">
      <type>transmission_interface/SimpleTransmission</type>
      <joint name="wx250s_forearm_roll">
        <!-- <hardwareInterface>hardware_interface/EffortJointInterface</hardwareInterface> -->
        <hardwareInterface>hardware_interface/PositionJointInterface</hardwareInterface>
      </joint>
      <actuator name="wx250s_forearm_roll_motor">
        <mechanicalReduction>1</mechanicalReduction>
      </actuator>
    </transmission>
    <!-- making the lower forearm link, for the rotation of the wrist -->
    <link name="firefly/wx250s/lower_forearm_link">
      <visual>
        <origin rpy="-1.5707963268 -3.14159265359 1.5707963268" xyz="0 0 0"/>
        <geometry>
          <mesh filename="package://rotors_description/meshes/wx250s/WXSA-250-M-5-LF.stl" scale="0.001 0.001 0.001"/>
        </geometry>
      </visual>
      <collision>
        <origin rpy="-1.5707963268 -3.14159265359 1.5707963268" xyz="0 0 0"/>
        <geometry>
          <mesh filename="package://rotors_description/meshes/wx250s/WXSA-250-M-5-LF.stl" scale="0.001 0.001 0.001"/>
        </geometry>
      </collision>
      <inertial>
        <origin rpy="0 0 0" xyz="0.0 0.0 0"/>
        <mass value="0.001"/>
        <inertia ixx="0.0000636900" ixy="-0.0000229200" ixz="0" iyy="0.0001677000" iyz="0" izz="0.0001834000"/>
      </inertial>
    </link>
    <!-- making the wrist joint, for the rotation of the wrist -->
    <joint name="wx250s_wrist_angle" type="revolute">
      <axis xyz="-1 0 0"/>
      <limit effort="100" lower="-2.14675497995" upper="1.74532925199" velocity="3.14159265359"/>
      <origin rpy="0.0 1.5707963268 0.0" xyz="0.0 -0.075 0.0"/>
      <parent link="firefly/wx250s/lower_forearm_link"/>
      <child link="firefly/wx250s/wrist_link"/>
    </joint>
    <!-- making the wrist servo, for the rotation of the wrist -->
    <transmission name="wx250s_trans_wrist_angle">
      <type>transmission_interface/SimpleTransmission</type>
      <joint name="wx250s_wrist_angle">
        <!-- <hardwareInterface>hardware_interface/EffortJointInterface</hardwareInterface> -->
        <hardwareInterface>hardware_interface/PositionJointInterface</hardwareInterface>
      </joint>
      <actuator name="wx250s_wrist_angle_motor">
        <mechanicalReduction>1</mechanicalReduction>
      </actuator>
    </transmission>
    <!-- making the wrist link, for the rotation of the wrist -->
    <link name="firefly/wx250s/wrist_link">
      <visual>
        <origin rpy="0 0 0" xyz="0 0 0"/>
        <geometry>
          <mesh filename="package://rotors_description/meshes/wx250s/WXSA-250-M-6-Wrist.stl" scale="0.001 0.001 0.001"/>
        </geometry>
        <material name="interbotix_black"/>
      </visual>
      <collision>
        <origin rpy="0 0 0" xyz="0 0 0"/>
        <geometry>
          <mesh filename="package://rotors_description/meshes/wx250s/WXSA-250-M-6-Wrist.stl" scale="0.001 0.001 0.001"/>
        </geometry>
      </collision>
      <inertial>
        <origin rpy="0 0 0" xyz="0.0423600000 0.0000106630 -0.0105770000"/>
        <mass value="0.001"/>
        <inertia ixx="0.0000308200" ixy="0.0000000191" ixz="0.0000000023" iyy="0.0000282200" iyz="0.0000025481" izz="0.0000315200"/>
      </inertial>
    </link>
    <!-- making the wrist joint, for the rotation of the wrist -->
    <joint name="wx250s_wrist_rotate" type="revolute">
      <axis xyz="0 1 0"/>
      <limit effort="100" lower="-3.14159265359" upper="3.14159265359" velocity="3.14159265359"/>
      <origin rpy="0 0 0" xyz="0.0 0.0 0.0"/>
      <parent link="firefly/wx250s/wrist_link"/>
      <child link="firefly/wx250s/gripper_link"/>
    </joint>
    <!-- making the wrist servo, for the rotation of the wrist -->
    <transmission name="wx250s_trans_wrist_rotate">
      <type>transmission_interface/SimpleTransmission</type>
      <joint name="wx250s_wrist_rotate">
        <!-- <hardwareInterface>hardware_interface/EffortJointInterface</hardwareInterface> -->
        <hardwareInterface>hardware_interface/PositionJointInterface</hardwareInterface>
      </joint>
      <actuator name="wx250s_wrist_rotate_motor">
        <mechanicalReduction>1</mechanicalReduction>
      </actuator>
    </transmission>
    <link name="firefly/wx250s/gripper_link">
      <visual>
        <origin rpy="0 0 0" xyz="0 -0.0448 0"/>
        <geometry>
          <mesh filename="package://rotors_description/meshes/wx250s/WXSA-250-M-7-Gripper.stl" scale="0.001 0.001 0.001"/>
        </geometry>
      </visual>
      <collision>
        <origin rpy="0 0 0" xyz="0 -0.0448 0"/>
        <geometry>
          <mesh filename="package://rotors_description/meshes/wx250s/WXSA-250-M-7-Gripper.stl" scale="0.001 0.001 0.001"/>
        </geometry>
      </collision>
      <inertial>
        <origin rpy="0 0 0" xyz="0.0216310000 0.0000002516 0.0114100000"/>
        <mass value="0.001"/>
        <inertia ixx="0.0000253700" ixy="0.0000000000" ixz="0.0000000000" iyy="0.0000183600" iyz="0.0000004340" izz="0.0000167400"/>
      </inertial>
    </link>
    <joint name="wx250s_ee_arm" type="fixed">
      <axis xyz="0 1 0"/>
      <origin rpy="0 0 0" xyz="0 0 0"/>
      <parent link="firefly/wx250s/gripper_link"/>
      <child link="firefly/wx250s/ee_arm_link"/>
    </joint>
    <link name="firefly/wx250s/ee_arm_link">
      <inertial>
        <mass value="0.001"/>
        <inertia ixx="0.001" ixy="0" ixz="0" iyy="0.001" iyz="0" izz="0.001"/>
      </inertial>
    </link>
    <joint name="wx250s_gripper_bar" type="fixed">
      <axis xyz="0 1 0"/>
      <origin rpy="0 0 0" xyz="0 0 0"/>
      <parent link="firefly/wx250s/ee_arm_link"/>
      <child link="firefly/wx250s/gripper_bar_link"/>
    </joint>
    <link name="firefly/wx250s/gripper_bar_link">
      <visual>
        <origin rpy="0 0 0" xyz="0 -0.042 0"/>
        <geometry>
          <mesh filename="package://rotors_description/meshes/wx250s/WXSA-250-M-9-Gripper-Bar.stl" scale="0.001 0.001 0.001"/>
        </geometry>
      </visual>
      <collision>
        <origin rpy="0 0 0" xyz="0 -0.042 0"/>
        <geometry>
          <mesh filename="package://rotors_description/meshes/wx250s/WXSA-250-M-9-Gripper-Bar.stl" scale="0.001 0.001 0.001"/>
        </geometry>
      </collision>
      <inertial>
        <origin rpy="0 0 0" xyz="0.0096870000 0.0000008177 0.0049620000"/>
        <mass value="0.001"/>
        <inertia ixx="0.0000074125" ixy="-0.0000000008" ixz="-0.0000000006" iyy="0.0000284300" iyz="-0.0000013889" izz="0.0000286000"/>
      </inertial>
    </link>
  </xacro:macro>
</robot>

